Workbook

Sheet TenderDataSheet
F1: Text Formatting
A2: 1 | B2: =IF(A2>26,CHAR(64+INT((A2-1)/26))&CHAR(65+MOD(A2-1,26)),CHAR(65+MOD(A2-1,26))) -> A | C2: Page | D2: Page Header | E2: IndianOil Corporation Limited (Marketing Division)
A3: 2 | B3: =IF(A3>26,CHAR(64+INT((A3-1)/26))&CHAR(65+MOD(A3-1,26)),CHAR(65+MOD(A3-1,26))) -> B | C3: Website | D3: Website for download | E3: www.indianoiltenders.com
A4: 3 | B4: =IF(A4>26,CHAR(64+INT((A4-1)/26))&CHAR(65+MOD(A4-1,26)),CHAR(65+MOD(A4-1,26))) -> C | C4: Address for Communication | D4: Addressed to : | E4: Dy. General Manager (Information Systems),
A5: 4 | B5: =IF(A5>26,CHAR(64+INT((A5-1)/26))&CHAR(65+MOD(A5-1,26)),CHAR(65+MOD(A5-1,26))) -> D | D5: Office Address (Line 1) | E5: 2nd Floor, Information Systems Department,
A6: 5 | B6: =IF(A6>26,CHAR(64+INT((A6-1)/26))&CHAR(65+MOD(A6-1,26)),CHAR(65+MOD(A6-1,26))) -> E | D6: Office Address (Line 2) | E6: IndianOil Corporation Limited,
A7: 6 | B7: =IF(A7>26,CHAR(64+INT((A7-1)/26))&CHAR(65+MOD(A7-1,26)),CHAR(65+MOD(A7-1,26))) -> F | D7: Office Address (Line 3) | E7: (Marketing Division) – Head Office,
A8: 7 | B8: =IF(A8>26,CHAR(64+INT((A8-1)/26))&CHAR(65+MOD(A8-1,26)),CHAR(65+MOD(A8-1,26))) -> G | D8: Office Address (Line 4) | E8: G-9, Ali Yavar Jung Marg,
A9: 8 | B9: =IF(A9>26,CHAR(64+INT((A9-1)/26))&CHAR(65+MOD(A9-1,26)),CHAR(65+MOD(A9-1,26))) -> H | D9: Office Address (Line 5) | E9: Bandra (East), Mumbai - 400 051
A10: 9 | B10: =IF(A10>26,CHAR(64+INT((A10-1)/26))&CHAR(65+MOD(A10-1,26)),CHAR(65+MOD(A10-1,26))) -> I | C10: Tender Reference | D10: Currency | E10: Rs. | G10: Currency in long text | H10: Rupees
A11: 10 | B11: =IF(A11>26,CHAR(64+INT((A11-1)/26))&CHAR(65+MOD(A11-1,26)),CHAR(65+MOD(A11-1,26))) -> J | D11: Tender Number | E11: HOSYS/61/PT-03/2025-26
A12: 11 | B12: =IF(A12>26,CHAR(64+INT((A12-1)/26))&CHAR(65+MOD(A12-1,26)),CHAR(65+MOD(A12-1,26))) -> K | D12: Tender Date | E12: 46006 | F12: DD-MMM-YYYY
A13: 12 | B13: =IF(A13>26,CHAR(64+INT((A13-1)/26))&CHAR(65+MOD(A13-1,26)),CHAR(65+MOD(A13-1,26))) -> L | D13: Description of Tender | E13: Implementation of IndianOil-SMILE (Salesforce Management for Insights, Loyalty and Efficiency) on SaaS platform along with Maintenance for 3 years
A14: 13 | B14: =IF(A14>26,CHAR(64+INT((A14-1)/26))&CHAR(65+MOD(A14-1,26)),CHAR(65+MOD(A14-1,26))) -> M | C14: Contacts | D14: Contact Person - 1 | E14: Sr.Manager(IS), Tel: 022 25447329 | G14: Contact Person - 2 | H14: Dy.Manager(IS), Tel: 022 25447823
A15: 14 | B15: =IF(A15>26,CHAR(64+INT((A15-1)/26))&CHAR(65+MOD(A15-1,26)),CHAR(65+MOD(A15-1,26))) -> N | D15: Contact Email - 1 | E15: email: sunambiar@indianoil.co.in | G15: Contact Email - 2 | H15: email: msrana@indianoil.in
A16: 15 | B16: =IF(A16>26,CHAR(64+INT((A16-1)/26))&CHAR(65+MOD(A16-1,26)),CHAR(65+MOD(A16-1,26))) -> O | C16: Sale of Tender | D16: Tender Sale Period From (date & time) | E16: =E12+TIME(10,0,0)+3 -> 46009.417 | F16: DD-MMM-YYYY at HH:MM \H\r\s I\ST
A17: 16 | B17: =IF(A17>26,CHAR(64+INT((A17-1)/26))&CHAR(65+MOD(A17-1,26)),CHAR(65+MOD(A17-1,26))) -> P | D17: Tender Sale Period Upto (date & time) | E17: =+E16+TIME(5,0,0)+12 -> 46021.625 | F17: DD-MMM-YYYY at HH:MM \H\r\s I\ST
A18: 17 | B18: =IF(A18>26,CHAR(64+INT((A18-1)/26))&CHAR(65+MOD(A18-1,26)),CHAR(65+MOD(A18-1,26))) -> Q | D18: Sale Hours | E18: on all working hours of days between Monday to Friday during 10:30 to 13:00 & 14:00 to 14:30
A19: 18 | B19: =IF(A19>26,CHAR(64+INT((A19-1)/26))&CHAR(65+MOD(A19-1,26)),CHAR(65+MOD(A19-1,26))) -> R | D19: Tender Fee (in Figs.) | E19: 0 | F19: ##,##,###
A20: 19 | B20: =IF(A20>26,CHAR(64+INT((A20-1)/26))&CHAR(65+MOD(A20-1,26)),CHAR(65+MOD(A20-1,26))) -> S | D20: Tender Fee (in Words) | E20: Two Thousand
A21: 20 | B21: =IF(A21>26,CHAR(64+INT((A21-1)/26))&CHAR(65+MOD(A21-1,26)),CHAR(65+MOD(A21-1,26))) -> T | D21: DD in favour of | E21: M/s Indian Oil Corporation Ltd., payable at Mumbai | F21: ##,##,###
A22: 21 | B22: =IF(A22>26,CHAR(64+INT((A22-1)/26))&CHAR(65+MOD(A22-1,26)),CHAR(65+MOD(A22-1,26))) -> U | C22: Address of Cash Secion | D22: Cash Section (Line 1) | E22: 4th Floor, Indian Oil Bhavan,
A23: 22 | B23: =IF(A23>26,CHAR(64+INT((A23-1)/26))&CHAR(65+MOD(A23-1,26)),CHAR(65+MOD(A23-1,26))) -> V | D23: Cash Section (Line 2) | E23: =E6 -> IndianOil Corporation Limited,
A24: 23 | B24: =IF(A24>26,CHAR(64+INT((A24-1)/26))&CHAR(65+MOD(A24-1,26)),CHAR(65+MOD(A24-1,26))) -> W | D24: Cash Section (Line 3) | E24: =E7 -> (Marketing Division) – Head Office,
A25: 24 | B25: =IF(A25>26,CHAR(64+INT((A25-1)/26))&CHAR(65+MOD(A25-1,26)),CHAR(65+MOD(A25-1,26))) -> X | D25: Cash Section (Line 4) | E25: =E8 -> G-9, Ali Yavar Jung Marg,
A26: 25 | B26: =IF(A26>26,CHAR(64+INT((A26-1)/26))&CHAR(65+MOD(A26-1,26)),CHAR(65+MOD(A26-1,26))) -> Y | D26: Cash Section (Line 5) | E26: =E9 -> Bandra (East), Mumbai - 400 051
A27: 26 | B27: =IF(A27>26,CHAR(64+INT((A27-1)/26))&CHAR(65+MOD(A27-1,26)),CHAR(65+MOD(A27-1,26))) -> Z | C27: Estimated Value | D27: Estimate Value (in Figures) | E27: 53.48 | F27: ##,##,##0.00 | G27: Unit (Eg: Lakhs/Crores etc.) : | H27: Crores
A28: 27 | B28: =IF(A28>26,CHAR(64+INT((A28-1)/26))&CHAR(65+MOD(A28-1,26)),CHAR(65+MOD(A28-1,26))) -> AA | D28: Estimate Value (in Words) | E28: Fifty Three Crores Forty Eight Lakhs
A29: 28 | B29: =IF(A29>26,CHAR(64+INT((A29-1)/26))&CHAR(65+MOD(A29-1,26)),CHAR(65+MOD(A29-1,26))) -> AB | C29: EMD | D29: Earnest Money Deposit (in Figs) | E29: =E27*10%*100 -> 534.8 | F29: ##,##,##0.0 | G29: Unit (Eg: Lakhs/Crores etc.) : | H29: Lakhs
A30: 29 | B30: =IF(A30>26,CHAR(64+INT((A30-1)/26))&CHAR(65+MOD(A30-1,26)),CHAR(65+MOD(A30-1,26))) -> AC | D30: Earnest Money Deposit (in Words) | E30: Five Crores Thirty Four Lakhs Eighty Thousand
D31: BG permissibility for above (in Figs.) | E31: 1 | F31: ##,##,##0.0 | G31: Unit (Eg: Lakhs/Crores etc.) : | H31: Lakhs
D32: BG permissibility for above (in Words) | E32: One | G32: Unit (Eg: Lakhs/Crores etc.) : | H32: Lakhs
A33: 30 | B33: =IF(A33>26,CHAR(64+INT((A33-1)/26))&CHAR(65+MOD(A33-1,26)),CHAR(65+MOD(A33-1,26))) -> AD | D33: Earnest Money Deposit Validity | E33: 4 (four) months
A34: 31 | B34: =IF(A34>26,CHAR(64+INT((A34-1)/26))&CHAR(65+MOD(A34-1,26)),CHAR(65+MOD(A34-1,26))) -> AE | C34: Pre-Bid | D34: Pre-Bid Conference (date & time) | E34: =+E16+TIME(0,30,0)+17 -> 46026.438 | F34: DD-MMM-YYYY at HH:MM \H\r\s I\ST
A35: 32 | B35: =IF(A35>26,CHAR(64+INT((A35-1)/26))&CHAR(65+MOD(A35-1,26)),CHAR(65+MOD(A35-1,26))) -> AF | D35: Pre-Bid Conference Venue (Line 1) | E35: =E5 -> 2nd Floor, Information Systems Department, | H35: =CHAR(65+MOD(A27-1,26)) -> Z
A36: 33 | B36: =IF(A36>26,CHAR(64+INT((A36-1)/26))&CHAR(65+MOD(A36-1,26)),CHAR(65+MOD(A36-1,26))) -> AG | D36: Pre-Bid Conference Venue (Line 2) | E36: =E6 -> IndianOil Corporation Limited, | H36: =MOD(A27,26) -> 0
A37: 34 | B37: =IF(A37>26,CHAR(64+INT((A37-1)/26))&CHAR(65+MOD(A37-1,26)),CHAR(65+MOD(A37-1,26))) -> AH | D37: Pre-Bid Conference Venue (Line 3) | E37: =E7 -> (Marketing Division) – Head Office,
A38: 35 | B38: =IF(A38>26,CHAR(64+INT((A38-1)/26))&CHAR(65+MOD(A38-1,26)),CHAR(65+MOD(A38-1,26))) -> AI | D38: Pre-Bid Conference Venue (Line 4) | E38: =E8 -> G-9, Ali Yavar Jung Marg,
A39: 36 | B39: =IF(A39>26,CHAR(64+INT((A39-1)/26))&CHAR(65+MOD(A39-1,26)),CHAR(65+MOD(A39-1,26))) -> AJ | D39: Pre-Bid Conference Venue (Line 5) | E39: =E9 -> Bandra (East), Mumbai - 400 051
A40: 37 | B40: =IF(A40>26,CHAR(64+INT((A40-1)/26))&CHAR(65+MOD(A40-1,26)),CHAR(65+MOD(A40-1,26))) -> AK | C40: Submission & Opening | D40: Submission of Tender (date & time) | E40: =+E34-TIMEVALUE(TEXT(E34,"hh:mm:ss"))+TIME(15,0,0)+6 -> 46032.625 | F40: DD-MMM-YYYY at HH:MM \H\r\s I\ST
...

Sheet MergerSheet
A1: PageHeader | B1: Web_site | C1: AddressedTo | D1: OfficeAddr1 | E1: OfficeAddr2 | F1: OfficeAddr3 | G1: OfficeAddr4 | H1: OfficeAddr5 | I1: Currency | J1: CurrencyWords | K1: TenderNo | L1: TenderDate | M1: NameOfTender | N1: ContactPerson1 | O1: ContactEmail1 | P1: ContactPerson2 | Q1: ContactEmail2 | R1: TenderSaleFrom | S1: TenderSaleUpto | T1: TenderSaleDuring | U1: TenderFee | V1: TenderFeeWords | W1: PmntInFavourOf | X1: CashSec_Addr1 | Y1: CashSec_Addr2 | Z1: CashSec_Addr3 | AA1: CashSec_Addr4 | AB1: CashSec_Addr5 | AC1: EstimateFigs | AD1: EstimateUnit | AE1: EstimateWords | AF1: EMDFigs | AG1: EMDUnit | AH1: EMDWords | AI1: EMDBGMinFigs | AJ1: EMDBGMinUnit | AK1: EMDMinWords | AL1: EMDValidity | AM1: PreBidDateTime | AN1: PreBidVenueAddr1 | AO1: PreBidVenueAddr2 | AP1: PreBidVenueAddr3 | AQ1: PreBidVenueAddr4 | AR1: PreBidVenueAddr5 | AS1: SubmitDateTime | AT1: OpenDateTime | AU1: TenderBoxLocn | AV1: ReceiptOfLOI | AW1: WorkCompletion | AX1: FAT | AY1: CompletionDelay | AZ1: PmntSchedule_1 | BA1: PmntSchedule_2 | BB1: PmntSchedule_3 | BC1: PmntSchedule_3_retention | BD1: ExperienceYrs | BE1: Experience | BF1: Order_1_Amt | BG1: Order_1_Unit | BH1: Order_2_Amt | BI1: Order_2_Unit | BJ1: Order_3_Amt | BK1: Order_3_Unit | BL1: TurnOverYr1 | BM1: TurnOverYr2 | BN1: TurnOverYr3 | BO1: AvgTurnOverCond | BP1: AvgTurnOverAmt | BQ1: AvgTurnOverUnit | BR1: WarrantyYrs | BS1: WarrantyFrom | BT1: CallAttendHrs | BU1: CallResolveHrs | BV1: FailOfParts | BW1: PenaltyDelayInAttn | BX1: VAT | BY1: Octroi | BZ1: SDpercent | CA1: SDwithinDays | CB1: SD_BGvalidity | CC1: PGvalue | CD1: PBGvalidity | CE1: Perf_Deficient
A2: =TenderDataSheet!E2 -> IndianOil Corporation Limited (Marketing Division) | B2: =TenderDataSheet!E3 -> www.indianoiltenders.com | C2: =TenderDataSheet!E4 -> Dy. General Manager (Information Systems), | D2: =TenderDataSheet!E5 -> 2nd Floor, Information Systems Department, | E2: =TenderDataSheet!E6 -> IndianOil Corporation Limited, | F2: =TenderDataSheet!E7 -> (Marketing Division) – Head Office, | G2: =TenderDataSheet!E8 -> G-9, Ali Yavar Jung Marg, | H2: =TenderDataSheet!E9 -> Bandra (East), Mumbai - 400 051 | I2: =TenderDataSheet!E10 -> Rs. | J2: =TenderDataSheet!H10 -> Rupees | K2: =TenderDataSheet!E11 -> HOSYS/61/PT-03/2025-26 | L2: =TEXT(TenderDataSheet!E12,TenderDataSheet!F12) -> 15-Dec-2025 | M2: =TenderDataSheet!E13 -> Implementation of IndianOil-SMILE (Salesforce Management for Insights, Loyalty and Efficiency) on SaaS platform along with Maintenance for 3 years | N2: =TenderDataSheet!E14 -> Sr.Manager(IS), Tel: 022 25447329 | O2: =TenderDataSheet!E15 -> email: sunambiar@indianoil.co.in | P2: =TenderDataSheet!H14 -> Dy.Manager(IS), Tel: 022 25447823 | Q2: =TenderDataSheet!H15 -> email: msrana@indianoil.in | R2: =TEXT(TenderDataSheet!E16,TenderDataSheet!F16) -> 18-Dec-2025 at 10:00 Hrs IST | S2: =TEXT(TenderDataSheet!E17,TenderDataSheet!F17) -> 30-Dec-2025 at 15:00 Hrs IST | T2: =TenderDataSheet!E18 -> on all working hours of days between Monday to Friday during 10:30 to 13:00 & 14:00 to 14:30 | U2: =TEXT(TenderDataSheet!E19,TenderDataSheet!F19) | V2: =TenderDataSheet!E20 -> Two Thousand | W2: =TEXT(TenderDataSheet!E21,TenderDataSheet!F21) -> M/s Indian Oil Corporation Ltd., payable at Mumbai | X2: =TenderDataSheet!E22 -> 4th Floor, Indian Oil Bhavan, | Y2: =TenderDataSheet!E23 -> IndianOil Corporation Limited, | Z2: =TenderDataSheet!E24 -> (Marketing Division) – Head Office, | AA2: =TenderDataSheet!E25 -> G-9, Ali Yavar Jung Marg, | AB2: =TenderDataSheet!E26 -> Bandra (East), Mumbai - 400 051 | AC2: =TEXT(TenderDataSheet!E27,TenderDataSheet!F27) -> 53.48 | AD2: =TenderDataSheet!H27 -> Crores | AE2: =TenderDataSheet!E28 -> Fifty Three Crores Forty Eight Lakhs | AF2: =TEXT(TenderDataSheet!E29,TenderDataSheet!F29) -> 534.8 | AG2: =TenderDataSheet!H29 -> Lakhs | AH2: =TenderDataSheet!E30 -> Five Crores Thirty Four Lakhs Eighty Thousand | AI2: =TEXT(TenderDataSheet!E31,TenderDataSheet!F31) -> 1.0 | AJ2: =TenderDataSheet!H32 -> Lakhs | AK2: =TenderDataSheet!E32 -> One | AL2: =TenderDataSheet!E33 -> 4 (four) months | AM2: =TEXT(TenderDataSheet!E34,TenderDataSheet!F34) -> 04-Jan-2026 at 10:30 Hrs IST | AN2: =TenderDataSheet!E35 -> 2nd Floor, Information Systems Department, | AO2: =TenderDataSheet!E36 -> IndianOil Corporation Limited, | AP2: =TenderDataSheet!E37 -> (Marketing Division) – Head Office, | AQ2: =TenderDataSheet!E38 -> G-9, Ali Yavar Jung Marg, | AR2: =TenderDataSheet!E39 -> Bandra (East), Mumbai - 400 051 | AS2: =TEXT(TenderDataSheet!E40,TenderDataSheet!F40) -> 10-Jan-2026 at 15:00 Hrs IST | AT2: =TEXT(TenderDataSheet!E41,TenderDataSheet!F41) -> 10-Jan-2026 at 15:30 Hrs IST | AU2: =TenderDataSheet!E42 -> in the Tender Box of (Information Systems) kept near the gate at the Main Entrance of IOCL | AV2: =TenderDataSheet!E43 -> 14 (fourteen) days | AW2: =TenderDataSheet!E44 -> 8 (eight) weeks | AX2: 7 (seven) weeks | AY2: =TenderDataSheet!E46 -> For any delay in completion of the work beyond the completion time stipulated, the contractual price payable by IOCL shall be subject to adjustment by way of discount in price by a sum equivalent to not more than 10% of the total contract value at the rate of ½% (half per cent) of the Purchase/Work Order value per week or part thereof of delay beyond the stipulated schedule date of completion | AZ2: =TenderDataSheet!E47 -> Seventy percent (70%) | BA2: =TenderDataSheet!E48 -> Twenty percent (20%) | BB2: =TenderDataSheet!E49 -> Ten percent (10%) | BC2: =TenderDataSheet!E50 -> 39 (thirty nine) calendar months | BD2: =TenderDataSheet!E51 -> Two (2) years ending 31st March 2010 | BE2: =TenderDataSheet!E52 -> experience of having successfully completed supplies of Servers and / or Storage (SAN) equipments with warranty support | BF2: =TEXT(TenderDataSheet!E53,TenderDataSheet!F53) -> 26.7 | BG2: =TenderDataSheet!H53 -> Crores | BH2: =TEXT(TenderDataSheet!E54,TenderDataSheet!F54) -> 21.4 | BI2: =TenderDataSheet!H54 -> Crores | BJ2: =TEXT(TenderDataSheet!E55,TenderDataSheet!F55) -> 16.0 | BK2: =TenderDataSheet!H55 -> Crores | BL2: =TenderDataSheet!E56 -> 2007-08 | BM2: =TenderDataSheet!E57 -> 2008-09 | BN2: =TenderDataSheet!E58 -> 2009-10 | BO2: =TenderDataSheet!E59 -> last 3 (Three) financial years, ending 31st March 2009 (2007-08, 2008-09, & 2009-10) | BP2: =TEXT(TenderDataSheet!E60,TenderDataSheet!F60) -> 3,208.8 | BQ2: =TenderDataSheet!H60 -> Lakhs | BR2: =TenderDataSheet!E61 -> 3 (three) years | BS2: =TenderDataSheet!E62 -> date of completion of installation of the last Server and SAN storage that is duly certified by IOCL | BT2: =TenderDataSheet!E63 -> 4 (four) hours | BU2: =TenderDataSheet!E64 -> 24 (twenty four) hours | BV2: =TenderDataSheet!E65 -> 48 (forty eight) hours | BW2: =TenderDataSheet!E66 -> the Number of Days of such delay, divided by the total Warranty Period in days and multiplied by Value of the Performance Guarantee | BX2: =TEXT(TenderDataSheet!E67,TenderDataSheet!F67) -> 10.30% | BY2: =TEXT(TenderDataSheet!E68,TenderDataSheet!F68) -> 5.5% | BZ2: =TenderDataSheet!E69 -> 10% (ten percent) | CA2: =TenderDataSheet!E70 -> 14 (fourteen) days | CB2: =TenderDataSheet!E71 -> 6 (six) calendar months | CC2: =TenderDataSheet!E72 -> 10% (ten percent) | CD2: =TenderDataSheet!E73 -> 39 (thirty nine) calendar months | CE2: =TenderDataSheet!E74 -> the Number of Days of experiencing of such deficiencies continually or otherwise even after duly informing the vendor of the same, divided by the total Warranty Period in days and multiplied by Value of the Performance Guarantee
